<mujoco model="mujoco_hand">
    <compiler angle="radian" coordinate="local"/>

    <asset>
        <mesh name="flange" file="meshes/mycobot_gripper/flange.STL" />
        <mesh name="gripper_base" file="meshes/mycobot_gripper/gripper_base.STL" />
        <mesh name="right_gear_link" file="meshes/mycobot_gripper/right_gear_link.STL" />
        <mesh name="right_finger_link" file="meshes/mycobot_gripper/right_finger_link.STL" />
        <mesh name="left_gear_link" file="meshes/mycobot_gripper/left_gear_link.STL" />
        <mesh name="left_finger_link" file="meshes/mycobot_gripper/left_finger_link.STL" />
        <mesh name="right_hinge_link" file="meshes/mycobot_gripper/right_hinge_link.STL" />
        <mesh name="left_hinge_link" file="meshes/mycobot_gripper/left_hinge_link.STL" />
    </asset>
    <actuator>
        <general biastype="affine" name="fingers_actuator" tendon="split" forcerange="-5 5"
        ctrlrange="0 255" gainprm="0.27 0 0" biasprm="0 -100 -10" forcelimited="true"
        ctrllimited="true" />
    </actuator>
    
    <tendon>
        <fixed name="split">
            <joint joint="robot0:right_gear_joint" coef="0.5" />
            <joint joint="robot0:left_gear_joint" coef="0.5" />
        </fixed>
    </tendon>

    <equality>
        <connect anchor="0.021833 -0.005 -0.0072346" body1="right_finger_link"
        body2="right_hinge_link"
        solimp="0.95 0.99 0.001" solref="0.005 1" />
        <connect anchor="0.021833 -0.005 0.0072347" body1="left_finger_link"
        body2="left_hinge_link"
        solimp="0.95 0.99 0.001" solref="0.005 1" />
        <joint joint1="robot0:right_gear_joint" joint2="robot0:left_gear_joint" polycoef="0 1 0 0 0"
        solimp="0.95 0.99 0.001" solref="0.005 1" />
    </equality>

    <contact>
        <exclude body1="right_finger_link" body2="right_hinge_link" />
        <exclude body1="left_finger_link" body2="left_hinge_link" />
        <exclude body1="left_finger_link" body2="right_finger_link" />
        <exclude body1="right_gear_link" body2="left_gear_link" />
    </contact>

    <worldbody>
        <body name="right_gripper" pos="0 0 0">
            <!-- <joint name="main_joint" pos="0 0 0" axis="1 0 0" type="slide"/> -->
            <body name="flange">
                <geom type="mesh" contype="1" conaffinity="1" group="1" density="0"
                    rgba="0.792157 0.819608 0.933333 1" mesh="flange" />
                <geom type="mesh" rgba="0.792157 0.819608 0.933333 1" mesh="flange" />
                <body name="gripper_camera_rgb_frame" pos="0.025 -0.043 0">
                    <body name="gripper_camera_rgb_optical_frame" pos="0 0 0"
                    quat="0.5 -0.5 0.5 -0.5">
                    <camera euler="3.1415 0 0" fovy="50" name="gripper_camera_rgb" pos="0 0 0"></camera>
                    </body>
                </body>
                <body name="gripper_camera_depth_frame" pos="0 0.045 0">
                    <body name="gripper_camera_depth_optical_frame" pos="0 0 0"
                    quat="0.5 -0.5 0.5 -0.5"></body>
                </body>
                <body euler="0 0 0" name="gripper_base" >
                    <body name="gripper_tcp" pos="0.13 -0.01 -0.001" />
                    <geom type="mesh" contype="0" conaffinity="0" group="1" density="0"
                    rgba="0.792157 0.819608 0.933333 1" mesh="gripper_base" />
                    <geom type="mesh" rgba="0.792157 0.819608 0.933333 1" mesh="gripper_base" />
                    <body name="right_gear_link" pos="0.0626 -0.00505 0.01225" >
                        <inertial pos="0.00313636 0.0026671 0.00586855"
                            quat="0.681896 0.190756 0.185171 0.681426" mass="0.00306867"
                            diaginertia="5.4546e-07 4.35596e-07 1.20909e-07" />
                        <joint name="robot0:right_gear_joint" pos="0 0 0" axis="0 1 0" range="0 0.7" armature="0.005" damping="0.1" solimplimit="0.95 0.99 0.001" solreflimit="0.005 1" limited="true" />
                        <geom type="mesh" contype="0" conaffinity="0" group="1" density="0"
                            rgba="0.792157 0.819608 0.933333 1" mesh="right_gear_link" />
                        <geom type="mesh" rgba="0.792157 0.819608 0.933333 1" mesh="right_gear_link" />
                        <body name="right_finger_link" pos="0.015573 -0.01 0.026804" >
                            <site name="ft_frame" pos="0 0 0" size="0.01 0.01 0.01" rgba="1 0 0 1" type="sphere" group="1"/>
                            <inertial pos="0.0324451 0.005 -0.0109997" quat="0 0.775032 0 0.631922"
                            mass="0.00694636" diaginertia="1.60061e-06 1.45682e-06 2.82185e-07" />
                            <joint name="right_finger_joint" pos="0 0 0" axis="0 -1 0" range="-0.872664 0.872664" solimplimit="0.95 0.99 0.001" solreflimit="0.005 1" limited="true" />
                            <geom type="mesh" contype="0" conaffinity="0" group="1" density="0"
                            rgba="0.792157 0.819608 0.933333 1" mesh="right_finger_link" />
                            <geom type="mesh" rgba="0.792157 0.819608 0.933333 1"
                            mesh="right_finger_link" />
                            <body name="right_finger_layer">
                                <geom name="right_finger_layer" type="box" size="0.013 0.01 0.001"
                                    pos="0.041 0.005 -0.021"
                                    condim="4" friction="2 0.3 0.1"
                                    solref="-20000 -500"
                                    solimp="0.999 0.999 0.001"></geom>
                            </body>
                        </body>
                    </body>
                    <body name="left_gear_link" pos="0.0626 -0.00505 -0.01325">
                        <inertial pos="0.00282687 0.00252761 -0.00562195"
                            quat="0.681488 -0.18894 -0.188164 0.68152" mass="0.00317605"
                            diaginertia="5.58215e-07 4.42379e-07 1.28181e-07" />
                        <joint name="robot0:left_gear_joint" pos="0 0 0" axis="0 -1 0" range="0 0.7" armature="0.005" damping="0.1" solimplimit="0.95 0.99 0.001" solreflimit="0.005 1" limited="true"/>
                        <geom type="mesh" contype="0" conaffinity="0" group="1" density="0"
                            rgba="0.792157 0.819608 0.933333 1" mesh="left_gear_link" />
                        <geom type="mesh" rgba="0.792157 0.819608 0.933333 1" mesh="left_gear_link" />
                        <body name="left_finger_link" pos="0.015455 -0.01 -0.026873">
                            <inertial pos="0.0324451 0.005 0.0109997" quat="0 0.631922 0 0.775032"
                            mass="0.00694636" diaginertia="1.60061e-06 1.45682e-06 2.82185e-07" />
                            <joint name="left_finger_joint" pos="0 0 0" axis="0 1 0" range="-0.872664 0.872664" solimplimit="0.95 0.99 0.001" solreflimit="0.005 1" limited="true" />
                            <geom type="mesh" contype="0" conaffinity="0" group="1" density="0"
                            rgba="0.792157 0.819608 0.933333 1" mesh="left_finger_link" />
                            <geom type="mesh" rgba="0.792157 0.819608 0.933333 1"
                            mesh="left_finger_link" />
                            <body name="left_finger_layer">
                            <geom name="left_finger_layer" type="box" size="0.013 0.01 0.001"
                                pos="0.041 0.005 0.021"
                                condim="4" friction="2 0.3 0.1" solref="-20000 -500"
                                solimp="0.999 0.999 0.001"></geom>
                            </body>
                        </body>
                    </body>
                    <body name="right_hinge_link" pos="0.08443 -0.02005 0.005">
                        <inertial pos="0.00766814 0.00999994 0.0132034" quat="0.965593 0 0.260056 0"
                            mass="0.00272533" diaginertia="4.80195e-07 3.55161e-07 1.60795e-07" />
                        <joint name="right_hinge_joint" pos="0 0 0" axis="0 1 0" solimplimit="0.95 0.99 0.001" solreflimit="0.005 1"/>
                        <geom type="mesh" contype="0" conaffinity="0" group="1" density="0"
                            rgba="0.792157 0.819608 0.933333 1" mesh="right_hinge_link" />
                        <geom type="mesh" rgba="0.792157 0.819608 0.933333 1"
                            mesh="right_hinge_link" />
                    </body>
                    <body name="left_hinge_link" pos="0.08443 -0.02005 -0.006">
                        <inertial pos="0.00784767 0.00999994 -0.013651"
                            quat="0.966166 0 -0.257923 0"
                            mass="0.00272533" diaginertia="4.80195e-07 3.55161e-07 1.60795e-07" />
                        <joint name="left_hinge_joint" pos="0 0 0" axis="0 1 0" solimplimit="0.95 0.99 0.001" solreflimit="0.005 1" />
                        <geom type="mesh" contype="0" conaffinity="0" group="1" density="0"
                            rgba="0.792157 0.819608 0.933333 1" mesh="left_hinge_link" />
                        <geom type="mesh" rgba="0.792157 0.819608 0.933333 1" mesh="left_hinge_link" />
                    </body>
                    <body name="eef" > 
                        <site name="grip_site" pos="0.13 -0.01 -0.001" rgba="0 0 1 1" size="0.005 0.005 0.005" />
                        <site name="grip_site_cylinder" pos="0.13 -0.01 -0.001" size="0.005 10" rgba="0 1 0 0.3" type="cylinder" group="1" quat="0 1 0 1"/>
                    </body>
                </body>
            </body> 
        </body>
    </worldbody>
    <sensor>
        <force name="force_ee" site="ft_frame"/>
        <torque name="torque_ee" site="ft_frame"/>
    </sensor>
</mujoco>